<?xml version="1.0" ?>
<!-- =================================================================================== -->
<!-- |    This document was autogenerated by xacro from airbot_cyton.xacro             | -->
<!-- |    EDITING THIS FILE BY HAND IS NOT RECOMMENDED                                 | -->
<!-- =================================================================================== -->
<robot name="airbot_cyton_gamma_1500" xmlns:xacro="http://www.ros.org/wiki/xacro">
  <link name="base_footprint">
    <visual>
      <origin rpy="0 0 0" xyz="0 0 0"/>
      <geometry>
        <sphere radius="0.001"/>
      </geometry>
      <material name="white">
        <color rgba="1 1 1 1"/>
      </material>
    </visual>
  </link>
  <link name="airbase">
    <visual>
      <origin rpy="0 0 0" xyz="0.0 0.0 0.0"/>
      <geometry>
        <mesh filename="package://gcop_urdf/meshes/quadrotor_base.dae" scale="3 3 1"/>
        <!--box size="0.44 0.44 0.1632"/-->
      </geometry>
      <material name="red">
        <color rgba="0.8 0 0 1"/>
      </material>
    </visual>
    <inertial>
      <mass value="4.2"/>
      <inertia ixx="0.3006565625" ixy="0.0" ixz="0.0" iyy="0.3006565625" iyz="0.0" izz="0.573313125"/>
    </inertial>
  </link>
  <!-- Joints -->
  <joint name="basetoairbase" type="fixed">
    <parent link="base_footprint"/>
    <child link="airbase"/>
    <origin rpy="0 0 0" xyz="0 0 0"/>
  </joint>
  <joint name="base_cyton_joint" type="fixed">
    <parent link="airbase"/>
    <child link="base_link"/>
    <origin rpy="3.14159265359 0 1.57079632679" xyz="0.0732 0.0 -0.1"/>
  </joint>
  <link name="base_link">
    <visual>
      <origin rpy="0 0 0" xyz="0 0 0"/>
      <geometry>
        <mesh filename="package://cyton_gamma_1500_description/meshes/base.dae"/>
      </geometry>
    </visual>
    <inertial>
      <origin xyz="0 0.0115 0.047"/>
      <mass value="0.24"/>
      <inertia ixx="0.0008033" ixy="0.0" ixz="0.0" iyy="0.00065104" iyz="0.0" izz="0.0011009"/>
    </inertial>
    <collision>
      <origin xyz="0 0.0115 0.047"/>
      <geometry>
        <box size="0.154 0.177 0.094"/>
      </geometry>
    </collision>
  </link>
  <joint name="shoulder_roll_joint" type="revolute">
    <parent link="base_link"/>
    <child link="shoulder_roll"/>
    <origin rpy="0 0 0.0" xyz="0 0 0.05315"/>
    <limit effort="1000.0" lower="-2.618" upper="2.618" velocity="1.0"/>
    <axis xyz="0 0 1"/>
    <dynamics damping="0.2" friction="0.0"/>
  </joint>
  <link name="shoulder_roll">
    <visual>
      <origin rpy="1.5708 0 0.384" xyz="0 0 0"/>
      <geometry>
        <mesh filename="package://cyton_gamma_1500_description/meshes/shoulder_roll.dae"/>
      </geometry>
    </visual>
    <inertial>
      <origin xyz="0 0 0.0907"/>
      <mass value="0.24"/>
      <inertia ixx="0.000799188226" ixy="0.0" ixz="0.0" iyy="0.00085155538" iyz="0.0" izz="0.00033406981"/>
    </inertial>
    <collision>
      <origin xyz="0 0 0.0907"/>
      <geometry>
        <box size="0.09829 0.08392 0.18143"/>
      </geometry>
    </collision>
  </link>
  <joint name="shoulder_pitch_joint" type="revolute">
    <parent link="shoulder_roll"/>
    <child link="shoulder_pitch"/>
    <origin rpy="0.0 0 0" xyz="0.0205 0 0.12435"/>
    <limit effort="500.0" lower="-1.8326" upper="1.8326" velocity="1.0"/>
    <axis xyz="1 0 0"/>
    <dynamics damping="0.1" friction="0.0"/>
  </joint>
  <link name="shoulder_pitch">
    <visual>
      <origin rpy="1.5708 0 0" xyz="0 0 0"/>
      <geometry>
        <mesh filename="package://cyton_gamma_1500_description/meshes/shoulder_pitch.dae"/>
      </geometry>
    </visual>
    <inertial>
      <origin xyz="-0.02 0.0 0.06"/>
      <mass value="0.24"/>
      <inertia ixx="0.0010265" ixy="0.0" ixz="0.0" iyy="0.00101" iyz="0.0" izz="0.0002725"/>
    </inertial>
    <collision>
      <origin xyz="-0.02 0.0 0.06"/>
      <geometry>
        <box size="0.08 0.085 0.21"/>
      </geometry>
    </collision>
  </link>
  <joint name="shoulder_yaw_joint" type="revolute">
    <parent link="shoulder_pitch"/>
    <child link="shoulder_yaw"/>
    <origin rpy="0 0.0 0" xyz="-0.0215 -0.0205 0.1255"/>
    <limit effort="200.0" lower="-1.8326" upper="1.8326" velocity="1.0"/>
    <axis xyz="0 -1 0"/>
    <dynamics damping="0.1" friction="0.0"/>
  </joint>
  <link name="shoulder_yaw">
    <visual>
      <origin rpy="1.5708 0 -1.5708" xyz="0 0 0.0"/>
      <geometry>
        <mesh filename="package://cyton_gamma_1500_description/meshes/shoulder_yaw.dae"/>
      </geometry>
    </visual>
    <inertial>
      <!--<origin xyz="-0.0225 0.039 0.3068"/>-->
      <origin xyz="0 0.025 0.0623"/>
      <mass value="0.14"/>
      <inertia ixx="0.000464246066667" ixy="0.0" ixz="0.0" iyy="0.000457543916667" iyz="0.0" izz="0.00012665625"/>
    </inertial>
    <collision>
      <origin xyz="0 0.025 0.0623"/>
      <geometry>
        <box size="0.0717 0.0756 0.1846"/>
      </geometry>
    </collision>
  </link>
  <joint name="elbow_pitch_joint" type="revolute">
    <parent link="shoulder_yaw"/>
    <child link="elbow_pitch"/>
    <origin rpy="0.0 0 0" xyz="0.018 0.0206 0.1158"/>
    <limit effort="100.0" lower="-1.8326" upper="1.8326" velocity="1.0"/>
    <axis xyz="1 0 0"/>
    <dynamics damping="0.1" friction="0.0"/>
  </joint>
  <link name="elbow_pitch">
    <visual>
      <origin rpy="1.5708 0 3.1416" xyz="0 0 0"/>
      <geometry>
        <mesh filename="package://cyton_gamma_1500_description/meshes/elbow_pitch.dae"/>
      </geometry>
    </visual>
    <inertial>
      <!--<origin xyz="0.0346 0.0461 0.4228"/>-->
      <origin xyz="-0.025 0.0 0.07785"/>
      <mass value="0.14"/>
      <inertia ixx="0.000350215716667" ixy="0.0" ixz="0.0" iyy="0.0003179925" iyz="0.0" izz="0.000102550116667"/>
    </inertial>
    <collision>
      <origin xyz="-0.025 0.0 0.07785"/>
      <geometry>
        <box size="0.0549 0.076 0.1557"/>
      </geometry>
    </collision>
  </link>
  <joint name="elbow_yaw_joint" type="revolute">
    <parent link="elbow_pitch"/>
    <child link="elbow_yaw"/>
    <origin rpy="0 0.0 0" xyz="-0.0171 -0.018 0.09746"/>
    <limit effort="100.0" lower="-1.8326" upper="1.8326" velocity="1.0"/>
    <axis xyz="0 -1 0"/>
    <dynamics damping="0.1" friction="0.0"/>
  </joint>
  <link name="elbow_yaw">
    <visual>
      <origin rpy="1.5708 0 1.5708" xyz="0 0 0"/>
      <geometry>
        <mesh filename="package://cyton_gamma_1500_description/meshes/elbow_yaw.dae"/>
      </geometry>
    </visual>
    <inertial>
      <origin xyz="0 0.02 0.058"/>
      <mass value="0.14"/>
      <inertia ixx="0.000175840466667" ixy="0.0" ixz="0.0" iyy="0.000190379583333" iyz="0.0" izz="5.22467166667e-05"/>
    </inertial>
    <collision>
      <origin xyz="0 0.02 0.058"/>
      <geometry>
        <box size="0.0535 0.0402 0.1160"/>
      </geometry>
    </collision>
  </link>
  <joint name="wrist_pitch_joint" type="revolute">
    <parent link="elbow_yaw"/>
    <child link="wrist_pitch"/>
    <origin rpy="0.0 0 0" xyz="0.02626 0.018 0.0718"/>
    <limit effort="50.0" lower="-1.8326" upper="1.8326" velocity="1.0"/>
    <axis xyz="-1 0 0"/>
    <dynamics damping="0.1" friction="0.0"/>
  </joint>
  <link name="wrist_pitch">
    <visual>
      <origin rpy="1.5708 0 1.5708" xyz="0 0 0"/>
      <geometry>
        <mesh filename="package://cyton_gamma_1500_description/meshes/wrist_pitch.dae"/>
      </geometry>
    </visual>
    <inertial>
      <origin xyz="-0.025925 0.013 0.01"/>
      <mass value="0.14"/>
      <inertia ixx="2.99629166667e-05" ixy="0.0" ixz="0.0" iyy="5.34411791667e-05" iyz="0.0" izz="3.92515958333e-05"/>
    </inertial>
    <collision>
      <origin xyz="-0.025925 0.013 0.01"/>
      <geometry>
        <box size="0.05185 0.026 0.0435"/>
      </geometry>
    </collision>
  </link>
  <joint name="wrist_roll_joint" type="revolute">
    <parent link="wrist_pitch"/>
    <child link="wrist_roll"/>
    <origin rpy="0 0 0.0" xyz="-0.026255 0 0.051425"/>
    <limit effort="50.0" lower="-2.61799" upper="2.61799" velocity="1.0"/>
    <axis xyz="0 0 1"/>
    <dynamics damping="0.1" friction="0.0"/>
  </joint>
  <link name="wrist_roll">
    <visual>
      <origin rpy="3.1416 0 -1.5708" xyz="0 0 0"/>
      <geometry>
        <mesh filename="package://cyton_gamma_1500_description/meshes/wrist_roll.dae"/>
      </geometry>
    </visual>
    <inertial>
      <origin xyz="0.0 -0.0014 0.03"/>
      <mass value="0.14"/>
      <inertia ixx="0.000187171716667" ixy="0.0" ixz="0.0" iyy="0.000157491133333" iyz="0.0" izz="9.22895166667e-05"/>
    </inertial>
    <collision>
      <origin xyz="0.0 -0.0014 0.03"/>
      <geometry>
        <box size="0.0518 0.0723 0.104"/>
      </geometry>
    </collision>
  </link>
  <!--<joint name="gripper_joint" type="prismatic">
    <parent link="wrist_roll"/>
    <child link="gripper_finger1"/>
    <origin rpy="0.0 0 0" xyz="-0.01331 0.00485 0.077225"/>
    <limit effort="25.0" lower="-0.008" upper="0.008" velocity="1.0"/>
    <axis xyz="1 0 0"/>
    <dynamics damping="0.1" friction="0.0"/>
  </joint>
  <link name="gripper_finger1">
    <visual>
      <origin rpy="0 0 0" xyz="0 0 0"/>
      <geometry>
        <mesh filename="package://cyton_gamma_1500_description/meshes/gripper_finger1.dae"/>
      </geometry>
    </visual>
    <inertial>
      <origin xyz="-0.005 0.0172 0.02"/>
      <mass value="0.05"/>
      <inertia ixx="1.15860833333e-05" ixy="0.0" ixz="0.0" iyy="1.03385416667e-05" iyz="0.0" izz="3.12254166667e-06"/>
    </inertial>
    <collision>
      <origin xyz="-0.005 0.0172 0.02"/>
      <geometry>
        <box size="0.015 0.0229 0.0475"/>
      </geometry>
    </collision>
  </link>
  <joint name="gripper_joint2" type="prismatic">
    <parent link="wrist_roll"/>
    <child link="gripper_finger2"/>
    <origin rpy="0 0 0" xyz="0.0098 0.00485 0.077225"/>
    <limit effort="25.0" lower="-0.008" upper="0.008" velocity="1.0"/>
    <mimic joint="gripper_joint" multiplier="-1"/>
    <axis xyz="1 0 0"/>
  </joint>
  <link name="gripper_finger2">
    <visual>
      <origin rpy="0 0 0" xyz="0 0 0"/>
      <geometry>
        <mesh filename="package://cyton_gamma_1500_description/meshes/gripper_finger2.dae"/>
      </geometry>
    </visual>
    <inertial>
      <origin xyz="0.005 0.0172 0.02"/>
      <mass value="0.05"/>
      <inertia ixx="1.15860833333e-05" ixy="0.0" ixz="0.0" iyy="1.03385416667e-05" iyz="0.0" izz="3.12254166667e-06"/>
    </inertial>
    <collision>
      <origin xyz="0.005 0.0172 0.02"/>
      <geometry>
        <box size="0.015 0.0229 0.0475"/>
      </geometry>
    </collision>
  </link>-->
  <joint name="virtual_endeffector_joint" type="fixed">
    <parent link="wrist_roll"/>
    <child link="virtual_endeffector"/>
    <origin rpy="0 0 0" xyz="-0.002316 0.0079 0.079425"/>
  </joint>
  <link name="virtual_endeffector">
    <visual>
      <origin rpy="0 0 0" xyz="0 0 0"/>
      <geometry>
        <sphere radius="0.002"/>
      </geometry>
      <material name="grey">
        <color rgba="0.7 0.7 0.7 0.8"/>
      </material>
    </visual>
    <inertial>
      <origin rpy="0 0 0" xyz="0 0 0"/>
      <mass value="1e-5"/>
      <inertia ixx="6.66666666667e-12" ixy="0.0" ixz="0.0" iyy="6.66666666667e-12" iyz="0.0" izz="6.66666666667e-12"/>
    </inertial>
  </link>
</robot>

